<?xml version="1.0" encoding="UTF-8"?>
<testng-results ignored="2" total="5" passed="2" failed="1" skipped="0">
  <reporter-output>
  </reporter-output>
  <suite started-at="2022-12-21T14:24:33 IST" name="Suite" finished-at="2022-12-21T14:25:49 IST" duration-ms="76116">
    <groups>
    </groups>
    <test started-at="2022-12-21T14:24:33 IST" name="Test" finished-at="2022-12-21T14:25:49 IST" duration-ms="76116">
      <class name="TestCases.VerifyCartValue">
        <test-method signature="VerifyCartVal()[pri:0, instance:TestCases.VerifyCartValue@5a56cdac]" started-at="2022-12-21T14:25:48 IST" name="VerifyCartVal" finished-at="2022-12-21T14:25:49 IST" duration-ms="895" status="PASS">
          <reporter-output>
          </reporter-output>
        </test-method> <!-- VerifyCartVal -->
      </class> <!-- TestCases.VerifyCartValue -->
      <class name="TestCases.LoginTestCase">
        <test-method is-config="true" signature="launch()[pri:0, instance:TestCases.LoginTestCase@2ed2d9cb]" started-at="2022-12-21T14:24:33 IST" name="launch" finished-at="2022-12-21T14:25:34 IST" duration-ms="61661" status="PASS">
          <reporter-output>
          </reporter-output>
        </test-method> <!-- launch -->
        <test-method signature="verifyLogin()[pri:0, instance:TestCases.LoginTestCase@2ed2d9cb]" started-at="2022-12-21T14:25:34 IST" name="verifyLogin" finished-at="2022-12-21T14:25:39 IST" duration-ms="4599" status="PASS">
          <reporter-output>
          </reporter-output>
        </test-method> <!-- verifyLogin -->
      </class> <!-- TestCases.LoginTestCase -->
      <class name="TestCases.MyAccountTestCase">
        <test-method signature="EditAccountDetails()[pri:0, instance:TestCases.MyAccountTestCase@593aaf41]" started-at="2022-12-21T14:25:39 IST" name="EditAccountDetails" finished-at="2022-12-21T14:25:48 IST" duration-ms="8848" status="FAIL">
          <exception class="java.lang.AssertionError">
            <message>
              <![CDATA[The following asserts failed:
expected [Success: Your account has successfully updated.] but found [Success: Your account has been successfully updated.]]]>
            </message>
            <full-stacktrace>
              <![CDATA[java.lang.AssertionError: The following asserts failed:
expected [Success: Your account has successfully updated.] but found [Success: Your account has been successfully updated.]
at org.testng.asserts.SoftAssert.assertAll(SoftAssert.java:47)
at org.testng.asserts.SoftAssert.assertAll(SoftAssert.java:31)
at Resources.CommonMethods.Assertion(CommonMethods.java:13)
at TestCases.MyAccountTestCase.EditAccountDetails(MyAccountTestCase.java:19)
at java.base/jdk.internal.reflect.NativeMethodAccessorImpl.invoke0(Native Method)
at java.base/jdk.internal.reflect.NativeMethodAccessorImpl.invoke(NativeMethodAccessorImpl.java:77)
at java.base/jdk.internal.reflect.DelegatingMethodAccessorImpl.invoke(DelegatingMethodAccessorImpl.java:43)
at java.base/java.lang.reflect.Method.invoke(Method.java:568)
at org.testng.internal.MethodInvocationHelper.invokeMethod(MethodInvocationHelper.java:133)
at org.testng.internal.TestInvoker.invokeMethod(TestInvoker.java:598)
at org.testng.internal.TestInvoker.invokeTestMethod(TestInvoker.java:173)
at org.testng.internal.MethodRunner.runInSequence(MethodRunner.java:46)
at org.testng.internal.TestInvoker$MethodInvocationAgent.invoke(TestInvoker.java:824)
at org.testng.internal.TestInvoker.invokeTestMethods(TestInvoker.java:146)
at org.testng.internal.TestMethodWorker.invokeTestMethods(TestMethodWorker.java:146)
at org.testng.internal.TestMethodWorker.run(TestMethodWorker.java:128)
at java.base/java.util.ArrayList.forEach(ArrayList.java:1511)
at org.testng.TestRunner.privateRun(TestRunner.java:794)
at org.testng.TestRunner.run(TestRunner.java:596)
at org.testng.SuiteRunner.runTest(SuiteRunner.java:377)
at org.testng.SuiteRunner.runSequentially(SuiteRunner.java:371)
at org.testng.SuiteRunner.privateRun(SuiteRunner.java:332)
at org.testng.SuiteRunner.run(SuiteRunner.java:276)
at org.testng.SuiteRunnerWorker.runSuite(SuiteRunnerWorker.java:53)
at org.testng.SuiteRunnerWorker.run(SuiteRunnerWorker.java:96)
at org.testng.TestNG.runSuitesSequentially(TestNG.java:1212)
at org.testng.TestNG.runSuitesLocally(TestNG.java:1134)
at org.testng.TestNG.runSuites(TestNG.java:1063)
at org.testng.TestNG.run(TestNG.java:1031)
at org.testng.remote.AbstractRemoteTestNG.run(AbstractRemoteTestNG.java:115)
at org.testng.remote.RemoteTestNG.initAndRun(RemoteTestNG.java:251)
at org.testng.remote.RemoteTestNG.main(RemoteTestNG.java:77)
]]>
            </full-stacktrace>
          </exception> <!-- java.lang.AssertionError -->
          <reporter-output>
          </reporter-output>
        </test-method> <!-- EditAccountDetails -->
      </class> <!-- TestCases.MyAccountTestCase -->
    </test> <!-- Test -->
  </suite> <!-- Suite -->
</testng-results>
